ERROR 2025-06-16 18:18:16,541 log Internal Server Error: /base/signup/
Traceback (most recent call last):
  File "C:\Users\Jatin\AppData\Roaming\Python\Python310\site-packages\django\core\handlers\exception.py", line 55, in inner
    response = get_response(request)
  File "C:\Users\Jatin\AppData\Roaming\Python\Python310\site-packages\django\core\handlers\base.py", line 197, in _get_response
    response = wrapped_callback(request, *callback_args, **callback_kwargs)
  File "C:\Users\Jatin\AppData\Roaming\Python\Python310\site-packages\django\views\decorators\csrf.py", line 56, in wrapper_view
    return view_func(*args, **kwargs)
  File "C:\Users\Jatin\AppData\Roaming\Python\Python310\site-packages\django\views\generic\base.py", line 104, in view
    return self.dispatch(request, *args, **kwargs)
  File "C:\Users\Jatin\AppData\Roaming\Python\Python310\site-packages\rest_framework\views.py", line 509, in dispatch
    response = self.handle_exception(exc)
  File "C:\Users\Jatin\AppData\Roaming\Python\Python310\site-packages\rest_framework\views.py", line 469, in handle_exception
    self.raise_uncaught_exception(exc)
  File "C:\Users\Jatin\AppData\Roaming\Python\Python310\site-packages\rest_framework\views.py", line 480, in raise_uncaught_exception
    raise exc
  File "C:\Users\Jatin\AppData\Roaming\Python\Python310\site-packages\rest_framework\views.py", line 506, in dispatch
    response = handler(request, *args, **kwargs)
  File "D:\My Work\urban_salon\Backend\urban_salon\base\base_views\SignUpView.py", line 91, in post
    username=username,
NameError: name 'username' is not defined
ERROR 2025-06-16 18:18:16,560 basehttp "POST /base/signup/ HTTP/1.1" 500 100020
ERROR 2025-06-16 18:19:04,999 log Internal Server Error: /base/signup/
Traceback (most recent call last):
  File "C:\Users\Jatin\AppData\Roaming\Python\Python310\site-packages\django\core\handlers\exception.py", line 55, in inner
    response = get_response(request)
  File "C:\Users\Jatin\AppData\Roaming\Python\Python310\site-packages\django\core\handlers\base.py", line 197, in _get_response
    response = wrapped_callback(request, *callback_args, **callback_kwargs)
  File "C:\Users\Jatin\AppData\Roaming\Python\Python310\site-packages\django\views\decorators\csrf.py", line 56, in wrapper_view
    return view_func(*args, **kwargs)
  File "C:\Users\Jatin\AppData\Roaming\Python\Python310\site-packages\django\views\generic\base.py", line 104, in view
    return self.dispatch(request, *args, **kwargs)
  File "C:\Users\Jatin\AppData\Roaming\Python\Python310\site-packages\rest_framework\views.py", line 509, in dispatch
    response = self.handle_exception(exc)
  File "C:\Users\Jatin\AppData\Roaming\Python\Python310\site-packages\rest_framework\views.py", line 469, in handle_exception
    self.raise_uncaught_exception(exc)
  File "C:\Users\Jatin\AppData\Roaming\Python\Python310\site-packages\rest_framework\views.py", line 480, in raise_uncaught_exception
    raise exc
  File "C:\Users\Jatin\AppData\Roaming\Python\Python310\site-packages\rest_framework\views.py", line 506, in dispatch
    response = handler(request, *args, **kwargs)
  File "D:\My Work\urban_salon\Backend\urban_salon\base\base_views\SignUpView.py", line 97, in post
    token = Token.objects.create(user=user)
AttributeError: type object 'Token' has no attribute 'objects'
ERROR 2025-06-16 18:19:05,022 basehttp "POST /base/signup/ HTTP/1.1" 500 100274
ERROR 2025-06-16 18:19:56,396 log Internal Server Error: /admin/base/users/
Traceback (most recent call last):
  File "C:\Users\Jatin\AppData\Roaming\Python\Python310\site-packages\django\db\backends\base\base.py", line 313, in _commit
    return self.connection.commit()
psycopg2.errors.ForeignKeyViolation: update or delete on table "base_users" violates foreign key constraint "base_userrolemapping_user_id_b5d2f248_fk_base_users_id" on table "base_userrolemapping"
DETAIL:  Key (id)=(deb3d595-a46f-4532-a807-9d43c517e3ac) is still referenced from table "base_userrolemapping".


The above exception was the direct cause of the following exception:

Traceback (most recent call last):
  File "C:\Users\Jatin\AppData\Roaming\Python\Python310\site-packages\django\core\handlers\exception.py", line 55, in inner
    response = get_response(request)
  File "C:\Users\Jatin\AppData\Roaming\Python\Python310\site-packages\django\core\handlers\base.py", line 197, in _get_response
    response = wrapped_callback(request, *callback_args, **callback_kwargs)
  File "C:\Users\Jatin\AppData\Roaming\Python\Python310\site-packages\django\contrib\admin\options.py", line 688, in wrapper
    return self.admin_site.admin_view(view)(*args, **kwargs)
  File "C:\Users\Jatin\AppData\Roaming\Python\Python310\site-packages\django\utils\decorators.py", line 134, in _wrapper_view
    response = view_func(request, *args, **kwargs)
  File "C:\Users\Jatin\AppData\Roaming\Python\Python310\site-packages\django\views\decorators\cache.py", line 62, in _wrapper_view_func
    response = view_func(request, *args, **kwargs)
  File "C:\Users\Jatin\AppData\Roaming\Python\Python310\site-packages\django\contrib\admin\sites.py", line 242, in inner
    return view(request, *args, **kwargs)
  File "C:\Users\Jatin\AppData\Roaming\Python\Python310\site-packages\django\utils\decorators.py", line 46, in _wrapper
    return bound_method(*args, **kwargs)
  File "C:\Users\Jatin\AppData\Roaming\Python\Python310\site-packages\django\utils\decorators.py", line 134, in _wrapper_view
    response = view_func(request, *args, **kwargs)
  File "C:\Users\Jatin\AppData\Roaming\Python\Python310\site-packages\django\contrib\admin\options.py", line 1983, in changelist_view
    response = self.response_action(
  File "C:\Users\Jatin\AppData\Roaming\Python\Python310\site-packages\django\contrib\admin\options.py", line 1593, in response_action
    response = func(self, request, queryset)
  File "C:\Users\Jatin\AppData\Roaming\Python\Python310\site-packages\django\contrib\admin\actions.py", line 51, in delete_selected
    modeladmin.delete_queryset(request, queryset)
  File "C:\Users\Jatin\AppData\Roaming\Python\Python310\site-packages\django\contrib\admin\options.py", line 1237, in delete_queryset
    queryset.delete()
  File "C:\Users\Jatin\AppData\Roaming\Python\Python310\site-packages\django\db\models\query.py", line 1148, in delete
    deleted, _rows_count = collector.delete()
  File "C:\Users\Jatin\AppData\Roaming\Python\Python310\site-packages\django\db\models\deletion.py", line 459, in delete
    with transaction.atomic(using=self.using, savepoint=False):
  File "C:\Users\Jatin\AppData\Roaming\Python\Python310\site-packages\django\db\transaction.py", line 263, in __exit__
    connection.commit()
  File "C:\Users\Jatin\AppData\Roaming\Python\Python310\site-packages\django\utils\asyncio.py", line 26, in inner
    return func(*args, **kwargs)
  File "C:\Users\Jatin\AppData\Roaming\Python\Python310\site-packages\django\db\backends\base\base.py", line 337, in commit
    self._commit()
  File "C:\Users\Jatin\AppData\Roaming\Python\Python310\site-packages\django\db\backends\base\base.py", line 312, in _commit
    with debug_transaction(self, "COMMIT"), self.wrap_database_errors:
  File "C:\Users\Jatin\AppData\Roaming\Python\Python310\site-packages\django\db\utils.py", line 91, in __exit__
    raise dj_exc_value.with_traceback(traceback) from exc_value
  File "C:\Users\Jatin\AppData\Roaming\Python\Python310\site-packages\django\db\backends\base\base.py", line 313, in _commit
    return self.connection.commit()
django.db.utils.IntegrityError: update or delete on table "base_users" violates foreign key constraint "base_userrolemapping_user_id_b5d2f248_fk_base_users_id" on table "base_userrolemapping"
DETAIL:  Key (id)=(deb3d595-a46f-4532-a807-9d43c517e3ac) is still referenced from table "base_userrolemapping".

ERROR 2025-06-16 18:19:56,431 basehttp "POST /admin/base/users/ HTTP/1.1" 500 162895
ERROR 2025-06-16 18:20:10,216 log Internal Server Error: /base/signup/
Traceback (most recent call last):
  File "C:\Users\Jatin\AppData\Roaming\Python\Python310\site-packages\django\core\handlers\exception.py", line 55, in inner
    response = get_response(request)
  File "C:\Users\Jatin\AppData\Roaming\Python\Python310\site-packages\django\core\handlers\base.py", line 197, in _get_response
    response = wrapped_callback(request, *callback_args, **callback_kwargs)
  File "C:\Users\Jatin\AppData\Roaming\Python\Python310\site-packages\django\views\decorators\csrf.py", line 56, in wrapper_view
    return view_func(*args, **kwargs)
  File "C:\Users\Jatin\AppData\Roaming\Python\Python310\site-packages\django\views\generic\base.py", line 104, in view
    return self.dispatch(request, *args, **kwargs)
  File "C:\Users\Jatin\AppData\Roaming\Python\Python310\site-packages\rest_framework\views.py", line 509, in dispatch
    response = self.handle_exception(exc)
  File "C:\Users\Jatin\AppData\Roaming\Python\Python310\site-packages\rest_framework\views.py", line 469, in handle_exception
    self.raise_uncaught_exception(exc)
  File "C:\Users\Jatin\AppData\Roaming\Python\Python310\site-packages\rest_framework\views.py", line 480, in raise_uncaught_exception
    raise exc
  File "C:\Users\Jatin\AppData\Roaming\Python\Python310\site-packages\rest_framework\views.py", line 506, in dispatch
    response = handler(request, *args, **kwargs)
  File "D:\My Work\urban_salon\Backend\urban_salon\base\base_views\SignUpView.py", line 80, in post
    token, _ = Token.objects.get_or_create(user=user)
AttributeError: type object 'Token' has no attribute 'objects'
ERROR 2025-06-16 18:20:10,424 basehttp "POST /base/signup/ HTTP/1.1" 500 100717
ERROR 2025-06-16 18:22:28,492 log Internal Server Error: /base/signup/
Traceback (most recent call last):
  File "C:\Users\Jatin\AppData\Roaming\Python\Python310\site-packages\django\core\handlers\exception.py", line 55, in inner
    response = get_response(request)
  File "C:\Users\Jatin\AppData\Roaming\Python\Python310\site-packages\django\core\handlers\base.py", line 197, in _get_response
    response = wrapped_callback(request, *callback_args, **callback_kwargs)
  File "C:\Users\Jatin\AppData\Roaming\Python\Python310\site-packages\django\views\decorators\csrf.py", line 56, in wrapper_view
    return view_func(*args, **kwargs)
  File "C:\Users\Jatin\AppData\Roaming\Python\Python310\site-packages\django\views\generic\base.py", line 104, in view
    return self.dispatch(request, *args, **kwargs)
  File "C:\Users\Jatin\AppData\Roaming\Python\Python310\site-packages\rest_framework\views.py", line 509, in dispatch
    response = self.handle_exception(exc)
  File "C:\Users\Jatin\AppData\Roaming\Python\Python310\site-packages\rest_framework\views.py", line 469, in handle_exception
    self.raise_uncaught_exception(exc)
  File "C:\Users\Jatin\AppData\Roaming\Python\Python310\site-packages\rest_framework\views.py", line 480, in raise_uncaught_exception
    raise exc
  File "C:\Users\Jatin\AppData\Roaming\Python\Python310\site-packages\rest_framework\views.py", line 506, in dispatch
    response = handler(request, *args, **kwargs)
  File "D:\My Work\urban_salon\Backend\urban_salon\base\base_views\SignUpView.py", line 81, in post
    token, _ = Token.objects.get_or_create(user=user)
AttributeError: type object 'Token' has no attribute 'objects'
ERROR 2025-06-16 18:22:28,505 basehttp "POST /base/signup/ HTTP/1.1" 500 100717
ERROR 2025-06-16 18:46:13,209 log Internal Server Error: /base/signup/
Traceback (most recent call last):
  File "C:\Users\Jatin\AppData\Roaming\Python\Python310\site-packages\django\core\handlers\exception.py", line 55, in inner
    response = get_response(request)
  File "C:\Users\Jatin\AppData\Roaming\Python\Python310\site-packages\django\core\handlers\base.py", line 197, in _get_response
    response = wrapped_callback(request, *callback_args, **callback_kwargs)
  File "C:\Users\Jatin\AppData\Roaming\Python\Python310\site-packages\django\views\decorators\csrf.py", line 56, in wrapper_view
    return view_func(*args, **kwargs)
  File "C:\Users\Jatin\AppData\Roaming\Python\Python310\site-packages\django\views\generic\base.py", line 104, in view
    return self.dispatch(request, *args, **kwargs)
  File "C:\Users\Jatin\AppData\Roaming\Python\Python310\site-packages\rest_framework\views.py", line 509, in dispatch
    response = self.handle_exception(exc)
  File "C:\Users\Jatin\AppData\Roaming\Python\Python310\site-packages\rest_framework\views.py", line 469, in handle_exception
    self.raise_uncaught_exception(exc)
  File "C:\Users\Jatin\AppData\Roaming\Python\Python310\site-packages\rest_framework\views.py", line 480, in raise_uncaught_exception
    raise exc
  File "C:\Users\Jatin\AppData\Roaming\Python\Python310\site-packages\rest_framework\views.py", line 506, in dispatch
    response = handler(request, *args, **kwargs)
  File "D:\My Work\urban_salon\Backend\urban_salon\base\base_views\SignUpView.py", line 81, in post
    token, _ = Token.objects.get_or_create(user=user)
AttributeError: type object 'Token' has no attribute 'objects'
ERROR 2025-06-16 18:46:13,235 basehttp "POST /base/signup/ HTTP/1.1" 500 100717
ERROR 2025-06-16 18:51:16,584 log Internal Server Error: /base/login/
Traceback (most recent call last):
  File "C:\Users\Jatin\AppData\Roaming\Python\Python310\site-packages\django\core\handlers\exception.py", line 55, in inner
    response = get_response(request)
  File "C:\Users\Jatin\AppData\Roaming\Python\Python310\site-packages\django\core\handlers\base.py", line 197, in _get_response
    response = wrapped_callback(request, *callback_args, **callback_kwargs)
  File "C:\Users\Jatin\AppData\Roaming\Python\Python310\site-packages\django\views\decorators\csrf.py", line 56, in wrapper_view
    return view_func(*args, **kwargs)
  File "C:\Users\Jatin\AppData\Roaming\Python\Python310\site-packages\django\views\generic\base.py", line 104, in view
    return self.dispatch(request, *args, **kwargs)
  File "C:\Users\Jatin\AppData\Roaming\Python\Python310\site-packages\rest_framework\views.py", line 509, in dispatch
    response = self.handle_exception(exc)
  File "C:\Users\Jatin\AppData\Roaming\Python\Python310\site-packages\rest_framework\views.py", line 469, in handle_exception
    self.raise_uncaught_exception(exc)
  File "C:\Users\Jatin\AppData\Roaming\Python\Python310\site-packages\rest_framework\views.py", line 480, in raise_uncaught_exception
    raise exc
  File "C:\Users\Jatin\AppData\Roaming\Python\Python310\site-packages\rest_framework\views.py", line 506, in dispatch
    response = handler(request, *args, **kwargs)
  File "D:\My Work\urban_salon\Backend\urban_salon\base\base_views\SignUpView.py", line 28, in post
    token, _ = Token.objects.get_or_create(user=user)
AttributeError: type object 'Token' has no attribute 'objects'
ERROR 2025-06-16 18:51:16,597 basehttp "POST /base/login/ HTTP/1.1" 500 100068
ERROR 2025-06-16 18:51:50,478 log Internal Server Error: /base/login/
Traceback (most recent call last):
  File "C:\Users\Jatin\AppData\Roaming\Python\Python310\site-packages\django\core\handlers\exception.py", line 55, in inner
    response = get_response(request)
  File "C:\Users\Jatin\AppData\Roaming\Python\Python310\site-packages\django\core\handlers\base.py", line 197, in _get_response
    response = wrapped_callback(request, *callback_args, **callback_kwargs)
  File "C:\Users\Jatin\AppData\Roaming\Python\Python310\site-packages\django\views\decorators\csrf.py", line 56, in wrapper_view
    return view_func(*args, **kwargs)
  File "C:\Users\Jatin\AppData\Roaming\Python\Python310\site-packages\django\views\generic\base.py", line 104, in view
    return self.dispatch(request, *args, **kwargs)
  File "C:\Users\Jatin\AppData\Roaming\Python\Python310\site-packages\rest_framework\views.py", line 509, in dispatch
    response = self.handle_exception(exc)
  File "C:\Users\Jatin\AppData\Roaming\Python\Python310\site-packages\rest_framework\views.py", line 469, in handle_exception
    self.raise_uncaught_exception(exc)
  File "C:\Users\Jatin\AppData\Roaming\Python\Python310\site-packages\rest_framework\views.py", line 480, in raise_uncaught_exception
    raise exc
  File "C:\Users\Jatin\AppData\Roaming\Python\Python310\site-packages\rest_framework\views.py", line 506, in dispatch
    response = handler(request, *args, **kwargs)
  File "D:\My Work\urban_salon\Backend\urban_salon\base\base_views\SignUpView.py", line 36, in post
    'refresh': str(refresh),
NameError: name 'token' is not defined
ERROR 2025-06-16 18:51:50,491 basehttp "POST /base/login/ HTTP/1.1" 500 101041
